<?xml version="1.0"?>
<robot name="px100" xmlns:xacro="http://ros.org/wiki/xacro">
  
  <xacro:property name="pi_offset" value="0.00001"/>
  <xacro:include filename="$(find robomaker_workshop)/config/px100.gazebo"/>

  <material name="interbotix_black">
    <texture filename="package://robomaker_workshop/media/materials/textures/interbotix_black.png"/>
  </material>

  <link name="world"/>
  <joint name="fixed" type="fixed">
    <parent link="world"/>
    <child link="px100/base_link"/>
  </joint>

  <link name="px100/base_link">
    <visual>
      <origin rpy="0 0 ${pi/2}" xyz="0 0 0"/>
      <geometry>
        <mesh filename="package://robomaker_workshop/meshes/px100_1_base.stl" scale="0.001 0.001 0.001"/>
      </geometry>
      <material name="interbotix_black"/>
    </visual>
    <collision>
      <origin rpy="0 0 ${pi/2}" xyz="0 0 0"/>
      <geometry>
        <mesh filename="package://robomaker_workshop/meshes/px100_1_base.stl" scale="0.001 0.001 0.001"/>
      </geometry>
    </collision>
    <inertial>
      <origin rpy="0 0 ${pi/2}" xyz="-0.0332053000 0.0008915770 0.0211913000"/>
      <mass value="0.395887" />
      <inertia ixx="0.0010650000" iyy="0.0003332000" izz="0.0012080000" ixy="-0.0000130300" ixz="0.0000018614" iyz="0.0000409200" />
    </inertial>
  </link>

  <joint name="waist" type="revolute">
    <axis xyz="0 0 1"/>
    <limit effort="1" lower="${-pi + pi_offset}" upper="${pi - pi_offset}" velocity="${pi}"/>
    <origin rpy="0 0 0" xyz="0 0 0.05085"/>
    <parent link="px100/base_link"/>
    <child link="px100/shoulder_link"/>
    <dynamics friction="0.1"/>
  </joint>

  <transmission name="trans_waist">
    <type>transmission_interface/SimpleTransmission</type>
    <joint name="waist">
      <hardwareInterface>hardware_interface/EffortJointInterface</hardwareInterface>
    </joint>
    <actuator name="waist_motor">
      <mechanicalReduction>1</mechanicalReduction>
    </actuator>
  </transmission>

  <link name="px100/shoulder_link">
    <visual>
      <origin rpy="0 0 ${pi/2}" xyz="0 0 -0.0022"/>
      <geometry>
        <mesh filename="package://robomaker_workshop/meshes/px100_2_shoulder.stl" scale="0.001 0.001 0.001"/>
      </geometry>
      <material name="interbotix_black"/>
    </visual>
    <collision>
      <origin rpy="0 0 ${pi/2}" xyz="0 0 -0.0022"/>
      <geometry>
        <mesh filename="package://robomaker_workshop/meshes/px100_2_shoulder.stl" scale="0.001 0.001 0.001"/>
      </geometry>
    </collision>
    <inertial>
      <origin rpy="0 0 ${pi/2}" xyz="0.0000111169 -0.0003605640 0.0284598000"/>
      <mass value="0.072587" />
      <inertia ixx="0.0000231000" iyy="0.0000253500" izz="0.0000144200" ixy="0.0000000003" ixz="0.0000001606" iyz="-0.0000000206" />
    </inertial>
  </link>

  <joint name="shoulder" type="revolute">
    <axis xyz="0 1 0"/>
    <limit effort="2" lower="${radians(-111)}" upper="${radians(107)}" velocity="${pi}"/>
    <origin rpy="0 0 0" xyz="0 0 0.04225"/>
    <parent link="px100/shoulder_link"/>
    <child link="px100/upper_arm_link"/>
    <dynamics friction="0.1"/>
  </joint>

  <transmission name="trans_shoulder">
    <type>transmission_interface/SimpleTransmission</type>
    <joint name="shoulder">
      <hardwareInterface>hardware_interface/EffortJointInterface</hardwareInterface>
    </joint>
    <actuator name="shoulder_motor">
      <mechanicalReduction>1</mechanicalReduction>
    </actuator>
  </transmission>

  <link name="px100/upper_arm_link">
    <visual>
      <origin rpy="0 0 ${pi/2}" xyz="0 0 0"/>
      <geometry>
        <mesh filename="package://robomaker_workshop/meshes/px100_3_upper_arm.stl" scale="0.001 0.001 0.001"/>
      </geometry>
      <material name="interbotix_black"/>
    </visual>
    <collision>
      <origin rpy="0 0 ${pi/2}" xyz="0 0 0"/>
      <geometry>
        <mesh filename="package://robomaker_workshop/meshes/px100_3_upper_arm.stl" scale="0.001 0.001 0.001"/>
      </geometry>
    </collision>
    <inertial>
      <origin rpy="0 0 ${pi/2}" xyz="0.0161976963 -0.0002929352 0.0877230000"/>
      <mass value="0.082923" />
      <inertia ixx="0.0000800600" iyy="0.0000745900" izz="0.0000368500" ixy="-0.0000002144" ixz="0.0000002982" iyz="0.0000165700" />
    </inertial>
  </link>

  <joint name="elbow" type="revolute">
    <axis xyz="0 1 0"/>
    <limit effort="2" lower="${radians(-121)}" upper="${radians(92)}" velocity="${pi}"/>
    <origin rpy="0 0 0" xyz="0.035 0 0.1"/>
    <parent link="px100/upper_arm_link"/>
    <child link="px100/forearm_link"/>
    <dynamics friction="0.1"/>
  </joint>

  <transmission name="trans_elbow">
    <type>transmission_interface/SimpleTransmission</type>
    <joint name="elbow">
      <hardwareInterface>hardware_interface/EffortJointInterface</hardwareInterface>
    </joint>
    <actuator name="elbow_motor">
      <mechanicalReduction>1</mechanicalReduction>
    </actuator>
  </transmission>

  <link name="px100/forearm_link">
    <visual>
      <origin rpy="0 0 ${pi/2}" xyz="0 0 0"/>
      <geometry>
        <mesh filename="package://robomaker_workshop/meshes/px100_4_forearm.stl" scale="0.001 0.001 0.001"/>
      </geometry>
      <material name="interbotix_black"/>
    </visual>
    <collision>
      <origin rpy="0 0 ${pi/2}" xyz="0 0 0"/>
      <geometry>
        <mesh filename="package://robomaker_workshop/meshes/px100_4_forearm.stl" scale="0.001 0.001 0.001"/>
      </geometry>
    </collision>
    <inertial>
      <origin rpy="0 0 ${pi/2}" xyz="0.0773720000 -0.0003324882 0.0000000000"/>
      <mass value="0.073058" />
      <inertia ixx="0.0000533800" iyy="0.0000165300" izz="0.0000603500" ixy="-0.0000003073" ixz="0.0000000000" iyz="0.0000000000" />
    </inertial>
  </link>

  <joint name="wrist_angle" type="revolute">
    <axis xyz="0 1 0"/>
    <limit effort="1" lower="${radians(-100)}" upper="${radians(123)}"  velocity="${pi}"/>
    <origin rpy="0 0 0" xyz="0.1 0 0"/>
    <parent link="px100/forearm_link"/>
    <child link="px100/gripper_link"/>
    <dynamics friction="0.1"/>
  </joint>

  <transmission name="trans_wrist_angle">
    <type>transmission_interface/SimpleTransmission</type>
    <joint name="wrist_angle">
      <hardwareInterface>hardware_interface/EffortJointInterface</hardwareInterface>
    </joint>
    <actuator name="wrist_angle_motor">
      <mechanicalReduction>1</mechanicalReduction>
    </actuator>
  </transmission>

  <link name="px100/gripper_link">
    <visual>
      <origin rpy="0 0 ${pi/2}" xyz="0 0 0"/>
      <geometry>
        <mesh filename="package://robomaker_workshop/meshes/px100_5_gripper.stl" scale="0.001 0.001 0.001"/>
      </geometry>
      <material name="interbotix_black"/>
    </visual>
    <collision>
      <origin rpy="0 0 ${pi/2}" xyz="0 0 0"/>
      <geometry>
        <mesh filename="package://robomaker_workshop/meshes/px100_5_gripper.stl" scale="0.001 0.001 0.001"/>
      </geometry>
    </collision>
    <inertial>
      <origin rpy="0 0 ${pi/2}" xyz="0.0446910000 0.0000000000 0.0113540000"/>
      <mass value="0.069929" />
      <inertia ixx="0.0000226800" iyy="0.0000204400" izz="0.0000197400" ixy="0.0000000000" ixz="0.0000000000" iyz="0.0000008485" />
    </inertial>
  </link>

  <joint name="ee_arm" type="fixed">
    <axis xyz="1 0 0"/>
    <origin rpy="0 0 0" xyz="0.063 0 0"/>
    <parent link="px100/gripper_link"/>
    <child link="px100/ee_arm_link"/>
  </joint>

  <link name="px100/ee_arm_link">
    <inertial>
      <mass value="0.001" />
      <inertia ixx="0.001" iyy="0.001" izz="0.001" ixy="0" ixz="0" iyz="0" />
    </inertial>
  </link>

  <joint name="gripper" type="continuous">
    <axis xyz="1 0 0"/>
    <limit effort="1" velocity="${pi}"/>
    <origin rpy="0 0 0" xyz="0.0055 0 0"/>
    <parent link="px100/ee_arm_link"/>
    <child link="px100/gripper_prop_link"/>
    <dynamics friction="0.1"/>
  </joint>

  <transmission name="trans_gripper">
    <type>transmission_interface/SimpleTransmission</type>
    <joint name="gripper">
      <hardwareInterface>hardware_interface/EffortJointInterface</hardwareInterface>
    </joint>
    <actuator name="gripper_motor">
      <mechanicalReduction>1</mechanicalReduction>
    </actuator>
  </transmission>

  <link name="px100/gripper_prop_link">
    <visual>
      <origin rpy="0 0 ${pi/2}" xyz="-0.0685 0 0"/>
      <geometry>
        <mesh filename="package://robomaker_workshop/meshes/px100_6_gripper_prop.stl" scale="0.001 0.001 0.001"/>
      </geometry>
      <material name="interbotix_black"/>
    </visual>
    <collision>
      <origin rpy="0 0 ${pi/2}" xyz="-0.0685 0 0"/>
      <geometry>
        <mesh filename="package://robomaker_workshop/meshes/px100_6_gripper_prop.stl" scale="0.001 0.001 0.001"/>
      </geometry>
    </collision>
    <inertial>
      <origin rpy="0 0 ${pi/2}" xyz="0.0008460000 -0.0000019330 0.0000420000"/>
      <mass value="0.00434" />
      <inertia ixx="0.0000005923" iyy="0.0000011156" izz="0.0000005743" ixy="0.0000000000" ixz="0.0000003195" iyz="-0.0000000004" />
    </inertial>
  </link>
  
  <!-- Gripper -->

  <joint name="gripper_bar" type="fixed">
    <axis xyz="1 0 0"/>
    <origin rpy="0 0 0" xyz="0 0 0"/>
    <parent link="px100/ee_arm_link"/>
    <child link="px100/gripper_bar_link"/>
  </joint>

  <link name="px100/gripper_bar_link">
    <visual>
      <origin rpy="0 0 ${pi/2}" xyz="-0.063 0 0"/>
      <geometry>
        <mesh filename="package://robomaker_workshop/meshes/px100_7_gripper_bar.stl" scale="0.001 0.001 0.001"/>
      </geometry>
      <material name="interbotix_black"/>
    </visual>
    <collision>
      <origin rpy="0 0 ${pi/2}" xyz="-0.063 0 0"/>
      <geometry>
        <mesh filename="package://robomaker_workshop/meshes/px100_7_gripper_bar.stl" scale="0.001 0.001 0.001"/>
      </geometry>
    </collision>
    <inertial>
      <origin rpy="0 0 ${pi/2}" xyz="0.0096870000 0.0000005660 0.0049620000"/>
      <mass value="0.034199" />
      <inertia ixx="0.0000074125" iyy="0.0000284300" izz="0.0000286000" ixy="-0.0000000008" ixz="-0.0000000006" iyz="-0.0000013889" />
    </inertial>
  </link>

  <joint name="ee_bar" type="fixed">
    <axis xyz="1 0 0"/>
    <origin rpy="0 0 0" xyz="0.023 0 0"/>
    <parent link="px100/gripper_bar_link"/>
    <child link="px100/fingers_link"/>
  </joint>

  <link name="px100/fingers_link">
    <inertial>
      <mass value="0.001" />
      <inertia ixx="0.001" iyy="0.001" izz="0.001" ixy="0" ixz="0" iyz="0" />
    </inertial>
  </link>


  <joint name="left_finger" type="prismatic">
    <axis xyz="0 1 0"/>
    <limit effort="5" lower="0.015" upper="0.037" velocity="1"/>
    <origin rpy="0 0 0" xyz="0 0 0"/>
    <parent link="px100/fingers_link"/>
    <child link="px100/left_finger_link"/>
    <dynamics friction="0.1"/>
  </joint>

  <transmission name="trans_left_finger">
    <type>transmission_interface/SimpleTransmission</type>
    <joint name="left_finger">
      <hardwareInterface>hardware_interface/EffortJointInterface</hardwareInterface>
    </joint>
    <actuator name="left_finger_motor">
      <mechanicalReduction>1</mechanicalReduction>
    </actuator>
  </transmission>

  <link name="px100/left_finger_link">
    <visual>
      <origin rpy="${pi} ${pi} 0" xyz="0 0.005 0"/>
      <geometry>
        <mesh filename="package://robomaker_workshop/meshes/px100_8_gripper_finger.stl" scale="0.001 0.001 0.001"/>
      </geometry>
      <material name="interbotix_black"/>
    </visual>
    <collision>
      <origin rpy="${pi} ${pi} 0" xyz="0 0.005 0"/>
      <geometry>
        <mesh filename="package://robomaker_workshop/meshes/px100_8_gripper_finger.stl" scale="0.001 0.001 0.001"/>
      </geometry>
    </collision>
    <inertial>
      <origin rpy="${pi} ${pi} ${pi/2}" xyz="0.0138160000 0.0000000000 0.0000000000"/>
       <mass value="0.016246" />
      <inertia ixx="0.0000047310" iyy="0.0000015506" izz="0.0000037467" ixy="-0.0000004560" ixz="0.0000000000" iyz="0.0000000000" />
    </inertial>
  </link>

  <joint name="right_finger" type="prismatic">
    <axis xyz="0 1 0"/>
    <limit effort="5" lower="-0.037" upper="-0.015" velocity="1"/>
    <origin rpy="0 0 0" xyz="0 0 0"/>
    <parent link="px100/fingers_link"/>
    <child link="px100/right_finger_link"/>
    <dynamics friction="0.1"/>
  </joint>

  <transmission name="trans_right_finger">
    <type>transmission_interface/SimpleTransmission</type>
    <joint name="right_finger">
      <hardwareInterface>hardware_interface/EffortJointInterface</hardwareInterface>
    </joint>
    <actuator name="right_finger_motor">
      <mechanicalReduction>1</mechanicalReduction>
    </actuator>
  </transmission>

  <link name="px100/right_finger_link">
    <visual>
      <origin rpy="0 ${pi} 0" xyz="0 -0.005 0"/>
      <geometry>
        <mesh filename="package://robomaker_workshop/meshes/px100_8_gripper_finger.stl" scale="0.001 0.001 0.001"/>
      </geometry>
      <material name="interbotix_black"/>
    </visual>
    <collision>
      <origin rpy="0 ${pi} 0" xyz="0 -0.005 0"/>
      <geometry>
        <mesh filename="package://robomaker_workshop/meshes/px100_8_gripper_finger.stl" scale="0.001 0.001 0.001"/>
      </geometry>
    </collision>
    <inertial>
      <origin rpy="0 ${pi} ${pi/2}" xyz="0.0138160000 0.0000000000  0.0000000000"/>
      <mass value="0.016246" />
      <inertia ixx="0.0000047310" iyy="0.0000015506" izz="0.0000037467" ixy="0.0000004560" ixz="0.0000000000" iyz="0.0000000000" />
    </inertial>
  </link>

  <joint name="ee_gripper" type="fixed">
    <axis xyz="1 0 0"/>
    <origin rpy="0 0 0" xyz="0.027575 0 0"/>
    <parent link="px100/fingers_link"/>
    <child link="px100/ee_gripper_link"/>
  </joint>

  <link name="px100/ee_gripper_link">
    <inertial>
      <mass value="0.001" />
      <inertia ixx="0.001" iyy="0.001" izz="0.001" ixy="0" ixz="0" iyz="0" />
    </inertial>
  </link>

</robot>
